<?xml version="1.0" ?>
<robot name="aka_robot" xmlns:xacro="http://ros.org/wiki/xacro">
  <xacro:include filename="$(find aka_robot_description)/urdf/common_properties.xacro"/>
  <xacro:include filename="$(find aka_robot_description)/urdf/aka_robot.gazebo.xacro"/>

  <link name="base_footprint"/>

  <joint name="base_joint" type="fixed">
    <parent link="base_footprint"/>
    <child link="base_link"/>
    <origin xyz="0.0 0.0 0.03" rpy="0 0 0"/>
  </joint>

  <link name="base_link">
    <visual>
      <origin xyz="0 0 0.0" rpy="0 0 0"/>
      <geometry>
        <mesh filename="package://aka_robot_description/meshes/base.dae"/>
      </geometry>
      <material name="light_black"/>
    </visual>

    <collision>
      <origin xyz="0 0 0.06" rpy="0 0 0"/>
      <geometry>
        <!-- <mesh filename="package://aka_robot_description/meshes/base.dae"/> -->
        <box size="0.35 0.25 0.05"/>
      </geometry>
    </collision>

    <inertial>
      <origin xyz="0 0 0" rpy="0 0 0"/>
      <mass value="8.2573504e-01"/>
      <inertia ixx="2.2124416e-03" ixy="-1.2294101e-05" ixz="3.4938785e-05"
               iyy="2.1193702e-03" iyz="-5.0120904e-06"
               izz="2.0064271e-03" />
    </inertial>
  </link>

  <joint name="wheel_left_joint" type="continuous">
    <parent link="base_link"/>
    <child link="wheel_left_link"/>
    <origin xyz="0.0 0.1 0.0" rpy="-1.57 0 0"/>
    <axis xyz="0 0 1"/>
  </joint>

  <link name="wheel_left_link">
    <visual>
      <origin xyz="0 0 0" rpy="-1.57 0 0"/>
      <geometry>
        <mesh filename="package://aka_robot_description/meshes/wheel.dae"/>
      </geometry>
      <material name="dark"/>
    </visual>

    <collision>
      <origin xyz="0 0 0" rpy="0 0 0"/>
      <geometry>
        <cylinder length="0.025" radius="0.03"/>
      </geometry>
    </collision>

    <inertial>
      <origin xyz="0 0 0" />
      <mass value="2.8498940e-02" />
      <inertia ixx="1.1175580e-05" ixy="-4.2369783e-11" ixz="-5.9381719e-09"
               iyy="1.1192413e-05" iyz="-1.4400107e-11"
               izz="2.0712558e-05" />
      </inertial>
  </link>

  <joint name="wheel_right_joint" type="continuous">
    <parent link="base_link"/>
    <child link="wheel_right_link"/>
    <origin xyz="0.0 -0.1 0.0" rpy="-1.57 0 0"/>
    <axis xyz="0 0 1"/>
  </joint>

  <link name="wheel_right_link">
    <visual>
      <origin xyz="0 0 0" rpy="-1.57 0 0"/>
      <geometry>
        <mesh filename="package://aka_robot_description/meshes/wheel.dae"/>
      </geometry>
      <material name="dark"/>
    </visual>

    <collision>
      <origin xyz="0 0 0" rpy="0 0 0"/>
      <geometry>
        <cylinder length="0.025" radius="0.03"/>
      </geometry>
    </collision>

    <inertial>
      <origin xyz="0 0 0" />
      <mass value="2.8498940e-02" />
      <inertia ixx="1.1175580e-05" ixy="-4.2369783e-11" ixz="-5.9381719e-09"
               iyy="1.1192413e-05" iyz="-1.4400107e-11"
               izz="2.0712558e-05" />
      </inertial>
  </link>

  <joint name="caster_front_joint" type="fixed">
    <parent link="base_link"/>
    <child link="caster_front_joint"/>
    <origin xyz="0.15 0 -0.005" rpy="0 0 0"/>
    <joint_properties damping="1.0" friction="1.0" />
  </joint>

  <link name="caster_front_joint">
    <!-- <visual>
      <origin xyz="0 0 0" rpy="0 0 0"/>
      <geometry>
        <mesh filename="package://aka_robot_description/meshes/caster.dae"/>
      </geometry>
      <material name="dark"/>
    </visual> -->

    <collision>
      <origin xyz="0 0 0.0001" rpy="0 0 0"/>
      <geometry>
        <!-- <box size="0.025 0.025 0.025"/> -->
        <sphere radius="0.02" />
      </geometry>
    </collision>

    <inertial>
      <origin xyz="0 0 0" />
      <mass value="0.005" />
      <inertia ixx="0.001" ixy="0.0" ixz="0.0"
               iyy="0.001" iyz="0.0"
               izz="0.001" />
    </inertial>
  </link>

  <joint name="caster_back_joint" type="fixed">
    <parent link="base_link"/>
    <child link="caster_back_link"/>
    <origin xyz="-0.15 0 -0.005" rpy="0 0 0"/>
    <joint_properties damping="1.0" friction="1.0" />
  </joint>

  <link name="caster_back_link">
    <!-- <visual>
      <origin xyz="0 0 0" rpy="0 0 0"/>
      <geometry>
        <mesh filename="package://aka_robot_description/meshes/caster.dae"/>
      </geometry>
      <material name="dark"/>
    </visual> -->
    
    <collision>
      <origin xyz="0 0 0.0001" rpy="0 0 0"/>
      <geometry>
        <!-- <box size="0.025 0.025 0.025"/> -->
        <sphere radius="0.02" />
      </geometry>
    </collision>

    <inertial>
      <origin xyz="0 0 0" />
      <mass value="0.005" />
      <inertia ixx="0.001" ixy="0.0" ixz="0.0"
               iyy="0.001" iyz="0.0"
               izz="0.001" />
    </inertial>
  </link>

  <!-- <joint name="imu_joint" type="fixed">
    <parent link="base_link"/>
    <child link="imu_link"/>
    <origin xyz="-0.032 0 0.068" rpy="0 0 0"/>
  </joint>

  <link name="imu_link"/> -->

  <joint name="scan_joint" type="fixed">
    <parent link="base_link"/>
    <child link="base_scan"/>
    <origin xyz="0.11 0 0.15" rpy="0 0 3.14159"/>
  </joint>

  <link name="base_scan">
    <visual>
      <origin xyz="0 0 0.0" rpy="0 0 3.14159"/>
      <geometry>
        <mesh filename="package://aka_robot_description/meshes/lidar.dae"/>
      </geometry>
      <material name="dark"/>
    </visual>

    <collision>
      <origin xyz="0.0 0 0" rpy="0 0 0"/>
      <geometry>
        <cylinder length="0.021" radius="0.035"/>
      </geometry>
    </collision>

    <inertial>
      <mass value="0.114" />
      <origin xyz="0 0 0" />
      <inertia ixx="0.001" ixy="0.0" ixz="0.0"
               iyy="0.001" iyz="0.0"
               izz="0.001" />
    </inertial>
  </link>

</robot>